Workbook

Sheet Cover Page
B2: GUI & FUNCTIONAL TEST CASES
B3: for <QUẢN LÝ BÁN HÀNG ONLINE>
B5: Document History – To maintain a list of changes being made
B6: Version | C6: Date | D6: Author | E6: Description of Changes
B7: <1.0> | D7: Lý Sơn Yến Ngọc | E7: Test requirement và test case cho web admin (tất cả)
D8: Trần Lâm Vũ | E8: Test requirement và test case cho web customer
D9: Hồ Thị Bảo Ngọc | E9: test GUI1
D10: Nguyễn Minh Quân | E10: test GUI2
D11: Nguyễn Thái Minh Trí | E11: test GUI3
B13: <1.1> | D13: Lý Sơn Yến Ngọc | E13: Test requirement và test case cho web admin ( quản lý sản phẩm, đăng nhập admin, thêm/sửa danh mục, quản lý chương trình giảm) giá )
D14: Trần Lâm Vũ | E14: Test requirement và test case cho web customer
D15: Hồ Thị Bảo Ngọc | E15: test GUI và test case tương ứng ( xóa danh mục, quản lý màu sắc, quản lý đơn hàng )
D16: Nguyễn Minh Quân | E16: test GUI và test case tương ứng (quản lý coupon, quản lý gói thành viên, thông tin cá nhân)
D17: Nguyễn Thái Minh Trí | E17: test GUI
B19: <1.2> | D19: Nguyễn Minh Quân | E19: tiếp tục làm testcase
D20: Trần Lâm Vũ | E20: tiếp tục làm testcase
D21: Nguyễn Thái Minh Trí | E21: tiếp tục làm testcase
D22: Hồ Thị Bảo Ngọc | E22: tiếp tục làm testcase
D23: Lý Sơn Yến Ngọc | E23: tiếp tục làm testcase
B25: <1.3> | D25: Nguyễn Minh Quân | E25: Execute Testing
D26: Trần Lâm Vũ | E26: Execute Testing
D27: Nguyễn Thái Minh Trí | E27: Execute Testing
D28: Hồ Thị Bảo Ngọc | E28: Execute Testing
D29: Lý Sơn Yến Ngọc | E29: Execute Testing
B30: This document has been generated from template ST-FunctionalTestCase-Template, version 1.2
B32: Reference Documents – Clearly mark the document used as an input to create the test case
B33: Version | C33: Date | D33: Document Name
B34: <x.y> | C34: <dd-Mmm-yyyy>

Sheet Test Requirements AD 
B2: Đưa ra các trường hợp test cho web admin
B5: General Information
B6: Project | D6: <Quản lý bán hàng online> | G6: Module | H6: <Người bán>
B7: Test Designed By | D7: Lý Sơn Yến Ngọc | G7: Reviewed By | H7: Hồ Thị Bảo Ngọc, Nguyễn Minh Quân, Nguyễn Thái Minh Trí
B8: Test Designed Date | G8: Reviewed Date | H8: <25-10-2025>
B11: List of Test Requirements
B12: No. | C12: Test Requirement ID | D12: Requirement Functions | E12: Mô tả chức năng | F12: Test Requirement Description | G12: Test Type | H12: Importance | I12: Status | J12: Number of TCs | K12: Note | L12: Test GUI | M12: Test Case
B13: 1 | C13: F1 | D13: Đăng nhập admin | E13: Đăng nhập vào hệ thống để quản lý | F13: Kiểm tra người dùng có thể đăng nhập được, đăng nhập không được, GUI | G13: Positive + Negative + LooknFeel | H13: High | I13: Pending | J13: =COUNTA('[1]Test Cases AD'!$D$5:$D$29) -> 5 | L13: GUI ĐĂNG NHẬP ADMIN | M13: TC ĐĂNG NHẬP
B14: 2 | C14: F2 | D14: DashBoard | E14: Hiển thị thông tin tổng quan dựa trên vai trò người dùng | F14: Admin: Thấy tất cả thống kê tổng quan. Nhân viên: Chỉ thấy dữ liệu liên quan | G14: Positive + Negative | H14: High | I14: Pending | J14: =COUNTA('[1]Test Cases AD'!$D$30:$D$64) -> 7 | M14: TC DASHBOARD
B15: 3 | C15: F3 | D15: Quản lý sản phẩm | E15: CRUD sản phẩm | F15: Kiểm tra chức năng quản lý toàn bộ sản phẩm (thêm, xem, sửa, xóa) | G15: Positive + Negative + LooknFeel | H15: High | I15: Pending | J15: =SUM(J16:J20) -> 66
B16: 4 | C16: F3.1 | D16: Thêm sản phẩm | E16: Tạo sản phẩm mới | F16: Kiểm tra thêm sản phẩm thành công, thất bại, GUI | G16: Positive + Negative + LooknFeel | H16: High | I16: Pending | J16: =COUNTA('[1]Test Cases AD'!$D$65:$D$174) -> 21 | L16: GUI THÊM SẢN PHẨM | M16: TC THÊM SẢN PHẨM
B17: 5 | C17: F3.2 | D17: Xem chi tiết sản phẩm | E17: Hiển thị thông tin SP | F17: Kiểm tra hiển thị đầy đủ thông tin chi tiết sản phẩm (hình ảnh, giá, thông số, đánh giá) | G17: Positive + Negative | H17: Medium | I17: Pending | J17: =COUNTA('[1]Test Cases AD'!$D$175:$D$229) -> 10 | M17: TC XEM CHI TIẾT SẢN PHẨM
B18: 6 | C18: F3.3 | D18: Xóa sản phẩm | E18: Xóa SP khỏi hệ thống | F18: Kiểm tra xóa sản phẩm thành công, thất bại và xác nhận trước khi xóa | G18: Positive + Negative | H18: High | I18: Pending | J18: =COUNTA('[1]Test Cases AD'!$D$230:$D$274) -> 8 | M18: TC XÓA SẢN PHẨM
B19: 7 | C19: F3.4 | D19: Sửa sản phẩm | E19: Cập nhật thông tin SP | F19: Kiểm tra cập nhật thông tin sản phẩm (giá, mô tả, hình ảnh, số lượng tồn kho) thành công, thất bại, GUI | G19: Positive + Negative + LooknFeel | H19: Medium | I19: Pending | J19: =COUNTA('[1]Test Cases AD'!$D$275:$D$348) -> 14 | L19: GUI SỬA SẢN PHẨM | M19: TC SỬA SẢN PHẨM
B20: 8 | C20: F3.5 | D20: Xem danh sách sản phẩm | E20: Tìm và lọc sản phẩm theo filter | F20: Kiểm tra tìm kiếm theo tên, lọc theo giá, hãng, RAM, bộ nhớ, màu sắc | G20: Positive + Negative | H20: High | I20: Pending | J20: =COUNTA('[1]Test Cases AD'!$D$349:$D$413) -> 13 | M20: TC XEM DANH SÁCH SẢN PHẨM
B21: 9 | C21: F4 | D21: Quản lý danh mục | E21: CRUD danh mục | F21: Kiểm tra quản lý danh mục sản phẩm (iPhone, Samsung, Xiaomi, Oppo, v.v.) | G21: Positive + Negative + LooknFeel | H21: Medium | I21: Pending | J21: =SUM(J22:J25) -> 33
B22: 10 | C22: F4.1 | D22: Thêm danh mục | E22: Tạo danh mục mới | F22: Kiểm tra thêm danh mục mới với tên và mô tả thành công, thất bại, GUI | G22: Positive + Negative + LooknFeel | H22: Medium | I22: Pending | J22: =COUNTA('[1]Test Cases AD'!$D$414:$D$453) -> 8 | L22: GUI THÊM DANH MỤC | M22: TC THÊM DANH MỤC
B23: 11 | C23: F4.2 | D23: Sửa danh mục | E23: Cập nhật danh mục | F23: Kiểm tra chỉnh sửa thông tin danh mục thành công, thất bại, GUI | G23: Positive + Negative + LooknFeel | H23: Medium | I23: Pending | J23: =COUNTA('[1]Test Cases AD'!$D$454:$D$508) -> 11 | L23: GUI SỬA DANH MỤC | M23: TC SỬA DANH MỤC
B24: 12 | C24: F4.3 | D24: Xóa danh mục | E24: Xóa danh mục | F24: Kiểm tra xóa danh mục thành công, thất bại và xử lý sản phẩm trong danh mục đó | G24: Positive + Negative | H24: Low | I24: Pending | J24: =COUNTA('[1]Test Cases AD'!$D$509:$D$533) -> 5 | M24: TC XÓA DANH MỤC
B25: 13 | C25: F4.4 | D25: Xem danh sách danh mục | E25: Hiển thị tất cả danh mục sản phẩm | F25: Kiểm tra danh sách các danh mục, lọc và tìm kiếm | G25: Positive + Negative | H25: High | I25: Pending | J25: =COUNTA('[1]Test Cases AD'!$D$534:$D$578) -> 9 | M25: TC XEM DANH SÁCH DANH MỤC
B26: 14 | C26: F5 | D26: Quản lý màu sắc | E26: CRUD màu sắc | F26: Kiểm tra quản lý màu sắc điện thoại (đen, trắng, xanh, đỏ, v.v.) | G26: Positive + Negative + LooknFeel | H26: Low | I26: Pending | J26: =SUM(J27:J29) -> 34
B27: 15 | C27: F5.1 | D27: Thêm màu sắc mới | E27: Tạo màu sắc mới | F27: Kiểm tra thêm tùy chọn màu sắc mới cho sản phẩm thành công, thất bại, GUI | G27: Positive + Negative + LooknFeel | H27: High | I27: Pending | J27: =COUNTA('[1]Test Cases AD'!$D$579:$D$638) -> 13 | L27: GUI THÊM MÀU SẮC | M27: TC THÊM MÀU SẮC
B28: 16 | C28: F5.2 | D28: Sửa màu sắc | E28: Cập nhật màu sắc | F28: Kiểm tra chỉnh sửa thông tin màu sắc thành công, thất bại, GUI | G28: Positive + Negative + LooknFeel | H28: Medium | I28: Pending | J28: =COUNTA('[1]Test Cases AD'!$D$639:$D$718) -> 16 | L28: GUI SỬA MÀU SẮC | M28: TC SỬA MÀU SẮC
B29: 17 | C29: F5.3 | D29: Xóa màu sắc | E29: Xóa màu sắc | F29: Kiểm tra xóa màu sắc khỏi hệ thống thành công, thất bại | G29: Positive + Negative | H29: Low | I29: Pending | J29: =COUNTA('[1]Test Cases AD'!$D$719:$D$743) -> 5 | M29: TC XÓA MÀU SẮC
B30: 18 | C30: F6 | D30: Quản lý chương trình giảm giá | E30: CRUD khuyến mãi | F30: Kiểm tra quản lý các chương trình giảm giá theo % hoặc số tiền cố định | G30: Positive + Negative + LooknFeel | H30: High | I30: Pending | J30: =SUM(J31:J34) -> 52
B31: 19 | C31: F6.1 | D31: Thêm chương trình giảm giá | E31: Tạo CT khuyến mãi | F31: Kiểm tra tạo chương trình giảm giá với thời gian bắt đầu/kết thúc, điều kiện áp dụng thành công, thất bại, GUI | G31: Positive + Negative + LooknFeel | H31: High | I31: Pending | J31: =COUNTA('[1]Test Cases AD'!$D$744:$D$841) -> 15 | L31: GUI THÊM CHƯƠNG TRÌNH GIẢM GIÁ | M31: TC THÊM CHƯƠNG TRÌNH GIẢM GIÁ
B32: 20 | C32: F6.2 | D32: Sửa chương trình giảm giá | E32: Cập nhật CT khuyến mãi | F32: Kiểm tra chỉnh sửa thông tin chương trình khuyến mãi thành công, thất bại, GUI | G32: Positive + Negative + LooknFeel | H32: Medium | I32: Pending | J32: =COUNTA('[1]Test Cases AD'!$D$842:$D$938) -> 15 | L32: GUI SỬA CHƯƠNG TRÌNH GIẢM GIÁ | M32: TC SỬA CHƯƠNG TRÌNH GIẢM GIÁ
B33: 21 | C33: F6.3 | D33: Xóa chương trình giảm giá | E33: Xóa CT khuyến mãi | F33: Kiểm tra xóa chương trình giảm giá thành công, thất bại và xử lý đơn hàng đã áp dụng | G33: Positive + Negative | H33: Medium | I33: Pending | J33: =COUNTA('[1]Test Cases AD'!$D$941:$D$978) -> 7 | M33: TC XÓA CHƯƠNG TRÌNH GIẢM GIÁ
B34: 22 | C34: F6.4 | D34: Xem danh sách chương trình giảm giá | E34: Hiển thị tất cả chương trình giảm giá | F34: Kiểm tra danh sách, lọc và tìm kiếm | G34: Positive + Negative | H34: Low | I34: Pending | J34: =COUNTA('[1]Test Cases AD'!$D$979:$D$1059) -> 15 | M34: TC XEM DANH SÁCH CHƯƠNG TRÌNH GIẢM GIÁ
B35: 23 | C35: F7 | D35: Quản lý đơn hàng | E35: Xử lý đơn hàng | F35: Kiểm tra quản lý toàn bộ quy trình đơn hàng từ tạo đến hoàn thành | G35: Positive + Negative + LooknFeel | H35: High | I35: Pending | J35: =SUM(J36:J40) -> 73
B36: 24 | C36: F7.1 | D36: Tạo đơn hàng | E36: Tạo mới đon hàng | F36: Kiểm tra tạo đơn hàng thành công, thất bại, GUI | G36: Positive + Negative + LooknFeel | H36: High | I36: Pending | J36: =COUNTA('[1]Test Cases AD'!$D$1062:$D$1200) -> 22 | L36: GUI TẠO ĐƠN HÀNG | M36: TC TẠO ĐƠN HÀNG
B37: 25 | C37: F7.2 | D37: Xem chi tiết đơn hàng | E37: Hiển thị chi tiết đơn hàng | F37: Kiểm tra hiển thị đầy đủ thông tin đơn hàng | G37: Positive + Negative | H37: Medium | I37: Pending | J37: 9 | M37: TC XEM CHI TIẾT ĐƠN HÀNG
B38: 26 | C38: F7.3 | D38: Sửa đơn hàng | E38: Sửa thông tin đơn hàng khi trạng thái đang xử lý | F38: Kiểm tra sửa thành công, thất bại , GUI | G38: Positive + Negative + LooknFeel | H38: Medium | I38: Pending | J38: =COUNTA('[1]Test Cases AD'!$D$1252:$D$1356) -> 21 | L38: GUI SỬA ĐƠN HÀNG | M38: TC SỬA ĐƠN HÀNG
B39: 27 | C39: F7.4 | D39: Hủy đơn hàng | E39: Huỷ đơn hàng | F39: Kiểm tra hủy đơn hàng thành công, thất bại | G39: Positive + Negative | H39: Medium | I39: Pending | J39: =COUNTA('[1]Test Cases AD'!$D$1357:$D$1396) -> 8 | M39: TC HỦY ĐƠN HÀNG
B40: 28 | C40: F7.5 | D40: Xem danh sách đơn hàng | E40: Xem danh sách đơn hàng | F40: Kiểm tra danh sách, lọc và tìm kiếm | G40: Positive + Negative | H40: Medium | I40: Pending | J40: =COUNTA('[1]Test Cases AD'!$D$1397:$D$1461) -> 13 | M40: TC XEM DANH SÁCH ĐƠN HÀNG
B41: 29 | C41: F8 | D41: Quản lý khách hàng | E41: CRUD khách hàng | F41: Kiểm tra quản lý thông tin khách hàng (xem, chặn, xóa) | G41: Positive + Negative + LooknFeel | H41: Medium | I41: Pending | J41: =SUM(J42:J43) -> 14
B42: 30 | C42: F8.1 | D42: Xem danh sách khách hàng | E42: Tìm và lọc danh sách theo filter | F42: Kiểm tra hiển thị danh sách khách hàng, lọc tìm kiếm khách hàng | G42: Positive + Negative | H42: Medium | I42: Pending | J42: =COUNTA('[1]Test Cases AD'!$D$1462:$D$1501) -> 8 | M42: TC XEM DANH SÁCH KHÁCH HÀNG
B43: 31 | C43: F8.2 | D43: Xem chi tiết khách hàng | E43: Hiển thị thông tin KH | F43: Kiểm tra xem thông tin chi tiết khách hàng thành công, thất bại | G43: Positive + Negative | H43: High | I43: Pending | J43: =COUNTA('[1]Test Cases AD'!$D$1502:$D$1533) -> 6 | M43: TC XEM CHI TIẾT KHÁCH HÀNG
B44: 32 | C44: F9 | D44: Quản lý coupon | E44: CRUD mã giảm giá | F44: Kiểm tra quản lý mã coupon/voucher giảm giá | G44: Positive + Negative + LooknFeel | H44: High | I44: Pending | J44: =SUM(J45:J49) -> 56
B45: 33 | C45: F9.1 | D45: Xem danh sách coupon | E45: Tìm và lọc coupon theo filter | F45: Kiểm tra hiển thị danh sách các coupon và tìm kiếm lọc theo filter | G45: Positive + Negative | H45: High | I45: Pending | J45: =COUNTA('[1]Test Cases AD'!$D$1534:$D$1558) -> 5 | M45: TC XEM DANH SÁCH COUPON
...

Sheet Test Requirements CUS
B2: Đưa ra các trường hợp test requirement cho web customer
B5: General Information
B6: Project | D6: <Quản lý bán hàng online> | G6: Module | H6: <Khách hàng>
B7: Test Designed By | D7: Trần Lâm Vũ | G7: Reviewed By | H7: Nguyễn Minh Quân,Lý Sơn Yến Ngọc
B8: Test Designed Date | G8: Reviewed Date
B11: List of Test Requirements
B12: No. | C12: Test Requirement ID | D12: Requirement Functions | E12: Mô tả chức năng | F12: Test Requirement Description | G12: Test Type | H12: Importance | I12: Status | J12: Number of TCs | K12: Note | L12: Test GUI | M12: Test Case
B13: 1 | C13: F1 | D13: Quản lý thông tin cá nhân | E13: Nhóm các chức năng về tài khoản người dùng | F13: Quản lý đăng nhập, đăng ký, đăng xuất đổi mật khẩu, quên mật khẩu, xem và cập nhậ thông tin cá nhân | G13: Postive +Negative | H13: High | I13: Pending
B14: 2 | C14: F1.1 | D14: Đăng nhập | E14: Người dùng đăng nhập hệ thống | F14: Kiểm tra người dùng đăng nhập thành công, thất bại, GUI | G14: Postive +Negative + LooknFeel | H14: High | I14: Pending | J14: =COUNTA('Test Cases CUS'!D13:D40) -> 7 | L14: GUI ĐĂNG NHẬP CUSTOMER | M14: TC ĐĂNG NHẬP
B15: 3 | C15: F1.2 | D15: Đăng ký tài khoản | E15: Người dùng đăng ký tài khoản mới | F15: Kiểm tra việc tạo tài khoản thành công, thất bại , GUI | G15: Postive +Negative + LooknFeel | H15: High | I15: Pending | J15: =COUNTA('Test Cases CUS'!D41:D95) -> 7 | L15: GUI ĐĂNG KÝ CUSTOMER | M15: TC ĐĂNG KÝ
B16: 4 | C16: F1.3 | D16: Cập nhật mật khẩu | E16: Cho phép người dùng thay đổi mật khẩu hiện tại | F16: Kiểm tra người dùng cập nhật mật khẩu mới thành công, thất bại | G16: Postive +Negative | H16: Medium | I16: Pending | J16: =COUNTA('Test Cases CUS'!D96:D113) -> 3 | M16: TC CẬP NHẬT MẬT KHẨU
B17: 5 | C17: F1.4 | D17: Quên mật khẩu | E17: Đặt lại mật khẩu | F17: Cho phép người dùng đặt lại mật khẩu qua email khi không nhớ mật khẩu cũ | G17: Postive +Negative | H17: Medium | I17: Pending | J17: =COUNTA('Test Cases CUS'!D114:D134) -> 3 | M17: TC QUÊN MẬT KHẨU
B18: 7 | C18: F1.5 | D18: Cập nhật thông tin cá nhân | E18: Chỉnh sửa hồ sơ | F18: Kiểm tra cập nhật thông tin người dùng: tên, số điện thoại, năm sinh | G18: Postive +Negative | H18: Medium | I18: Pending | J18: =COUNTA('Test Cases CUS'!D135:D231) -> 19 | L18: GUI CẬP NHẬT THÔNG TIN CÁ NHÂN CUSTOMER | M18: TC CẬP NHẬT THÔNG TIN CÁ NHÂN
B19: 8 | C19: F1.6 | D19: Đăng xuất | E19: Thoát khỏi tài khoản | F19: Kiểm tra đăng xuất và xóa session người dùng | G19: Postive +Negative | H19: Medium | I19: Pending | J19: =COUNTA('Test Cases CUS'!D232:D243) -> 1 | M19: TC ĐĂNG XUẤT
B20: 9 | C20: F2 | D20: Quản lý giỏ hàng | E20: Nhóm chức năng về giỏ hàng | F20: Cho phép người dùng thêm, sửa, xoá sản phầm trong giỏ hàng | G20: Postive +Negative | H20: High | I20: Pending
B21: 10 | C21: F2.1 | D21: Tìm kiếm sản phẩm | E21: Người dùng tìm sản phẩm theo tên hoặc mã, tìm kiếm nâng cao (lọc theo giá, tên, danh mục…) | F21: Kiểm tra tìm kiếm sản phẩm thành công, thất bại | G21: Postive +Negative | H21: High | I21: Pending | J21: =COUNTA('Test Cases CUS'!D244:D263) -> 6 | M21: TC TÌM KIẾM SẢN PHẨM
B22: 16 | C22: F2.2 | D22: Xem chi tiết sản phẩm | E22: Người dùng xem thông tin chi tiết sản phẩm | F22: Kiểm tra xem chi tiết sản phẩm thành công, thất bại | G22: Postive +Negative | H22: Medium | I22: Pending | J22: =COUNTA('Test Cases CUS'!D264:D298) -> 10 | M22: TC XEM CHI TIẾT SẢN PHẨM
B23: 17 | C23: F2.3 | D23: Thêm sản phẩm vào giỏ hàng | E23: Người dùng thêm sản phẩm vào giỏ hàng | F23: Kiểm tra thêm sản phẩm vào giỏ hàng thành công, thất bại | G23: Postive +Negative | H23: Medium | I23: Pending | J23: =COUNTA('Test Cases CUS'!D299:D374) -> 15 | M23: TC THÊM SẢN PHẨM VÀO GIỎ HÀNG
B24: 18 | C24: F2.4 | D24: Xem giỏ hàng | E24: Người dùng xem các sản phẩm trong giỏ | F24: Kiểm tra xem giỏ hàng thành công, thất bại | G24: Postive +Negative | H24: Medium | I24: Pending | J24: =COUNTA('Test Cases CUS'!D375:D400) -> 4 | M24: TC XEM GIỎ HÀNG
B25: 19 | C25: F2.4.1 | D25: Xoá sản phẩm khỏi giỏ hàng | E25: Người dùng xoá sản phẩm không muốn mua | F25: Kiểm tra xóa sản phẩm khỏi giỏ hàng thành công, thất bại | G25: Postive +Negative | H25: Medium | I25: Pending | J25: =COUNTA('Test Cases CUS'!D401:D425) -> 4 | M25: TC XOÁ SẢN PHẨM KHỎI GIỎ HÀNG
B26: 20 | C26: F2.4.2 | D26: Sửa số lượng sản phẩm | E26: Người dùng tăng, giảm số lượng sản phẩm trong giỏ | F26: Kiểm tra tăng, giảm số lượng sản phẩm trong giỏ hàng thành công, thất bại | G26: Postive | H26: Medium | I26: Pending | J26: =COUNTA('Test Cases CUS'!D426:D464) -> 7 | M26: TC SỬA SỐ LƯỢNG SẢN PHẨM
B27: 21 | C27: F3 | D27: Theo dõi đơn hàng | E27: Cho phép người dùng theo dõi đơn hàng đã mua, mới mua, đang vận chuyển | F27: Kiểm tra danh sách đơn hàng đã mua, mới mua, đang vận chuyển, đã vận chuyển | G27: Postive +Negative | H27: Medium | I27: Pending
B28: 22 | C28: F3.1 | D28: Xem danh sách đơn hàng | E28: Người dùng xem danh sách đơn hàng | F28: Kiểm tra xem danh sách đơn hàng thành công, thất bại, tìm kiếm nâng cao (theo trạng thái, ngày….) | G28: Postive +Negative | H28: High | I28: Pending | J28: =COUNTA('Test Cases CUS'!D465:D540) -> 12 | M28: TC XEM DANH SÁCH ĐƠN HÀNG
B29: 23 | C29: F3.2 | D29: Xem chi tiết đơn hàng | E29: Người dùng xem chi tiết đơn hàng của mình | F29: Kiểm tra người dùng xem chi tiết đơn hàng thành công, thất bại | G29: Postive +Negative | H29: High | I29: Pending | J29: =COUNTA('Test Cases CUS'!D541:D566) -> 5 | M29: TC XEM CHI TIẾT ĐƠN HÀNG
B30: 22 | C30: F3.3 | D30: Hủy đơn hàng | E30: Người dùng đơn hàng khi còn ở trạng thái "Chờ xác nhận" | F30: Kiểm tra hủy thành công, không cho hủy khi đã xử lý | G30: Postive +Negative | H30: Medium | I30: Pending | J30: =COUNTA('Test Cases CUS'!D567:D608) -> 6 | M30: TC HỦY ĐƠN HÀNG
B31: 24 | C31: F4 | D31: Mua hàng | E31: Mua sản phẩm | F31: Kiểm tra mua sản phẩm thành công, thất bại | G31: Postive +Negative | H31: High | I31: Pending | J31: =COUNTA('Test Cases CUS'!D609:D670) -> 11 | M31: TC MUA HÀNG
J32: =SUM(J13:J31) -> 120

Sheet TestCase AD
A1: Test Cases for 'Quản lý bán hàng online' function
K2: Execute Testing - Version1.0
A3: No. | B3: Test Requirement ID | C3: Test Case ID | D3: Test Objective | E3: Pre-conditions | F3: Step # | G3: Step Action | H3: Test Data | I3: Expected Result | J3: Passed | K3: Result | L3: By tester | M3: Note
A4: Functional TCs
A5: 1 | B5: F1 | C5: F1_00 | D5: Kiểm tra giao diện đăng nhập admin | E5: Vào được trang đăng nhập | F5: 1 | G5: Mở trang đăng nhập | I5: Giao diện được thiết kế đúng theo yêu cầu | J5: Passed | K5: Passed | L5: Lý Sơn Yến Ngọc
F6: 2 | G6: Check giao diện theo form | H6: form đăng nhập
F7: 3 | G7: Check giao diện theo checklist gui | H7: checklist gui
B10: BACK | C10: F1_01 | D10: Đăng nhập thành công | E10: Tài khoản đã được đăng ký trước đó | F10: 1 | G10: Mở trang đăng nhập | I10: Đăng nhập thành công chuyển hướng đến trang Admin | K10: Passed | L10: Lý Sơn Yến Ngọc
F11: 2 | G11: Nhập tên đăng nhập hợp lệ | H11: admin1
F12: 3 | G12: Nhập mật khẩu hợp lệ | H12: 123
F13: 4 | G13: Click nút đăng nhập
C15: F1_02 | D15: Đăng nhập thất bại | E15: Không có | F15: 1 | G15: Mở trang đăng nhập | I15: Hiển thị thông báo tên đăng nhập hoặc mật khẩu không đúng | K15: Passed | L15: Lý Sơn Yến Ngọc
F16: 2 | G16: Nhập tên đăng nhập không tồn tại | H16: admin2
F17: 3 | G17: Nhập mật khẩu bất kỳ | H17: 123
F18: 4 | G18: Click nút đăng nhập
C20: F1_03 | D20: Đăng nhập thất bại với mật khẩu sai | E20: Tài khoản đã tồn tại | F20: 1 | G20: Mở trang đăng nhập | I20: Hiển thị thông báo tên đăng nhập hoặc mật khẩu không đúng | K20: Passed | L20: Lý Sơn Yến Ngọc
F21: 2 | G21: Nhập tên đăng nhập hợp lệ | H21: admin1
F22: 3 | G22: Nhập mật khẩu sai | H22: 456
F23: 4 | G23: Click nút đăng nhập
C25: F1_04 | D25: Đăng nhập với trường bỏ trống | E25: Không có | F25: 1 | G25: Mở trang đăng nhập | I25: Hiển thị thông báo vui lòng nhập email và vui lòng nhập mật khẩu | K25: Passed | L25: Lý Sơn Yến Ngọc
F26: 2 | G26: Để trống tên đăng nhập
F27: 3 | G27: Để trống mật khẩu
F28: 4 | G28: Click nút đăng nhập
A30: 3 | B30: F2 | C30: F2_01 | D30: Kiểm tra hiển thị dashboard chính xác với vai trò Admin | E30: Hệ thống đã có dữ liệu (ví dụ: 100 đơn hàng, 50.000.000đ tổng doanh thu) | F30: 1 | G30: Truy cập trang dashboard | I30: Hệ thống hiển thị trang Dashboard với đầy đủ các thông tin tổng quan của toàn hệ thống: | K30: Passed | L30: Lý Sơn Yến Ngọc
B35: BACK | C35: F2_02 | D35: Kiểm tra hiển thị dashboard chính xác với vai trò Nhân viên Bán hàng | E35: Có dữ liệu riêng (ví dụ: 10 đơn hàng đã xử lý, 5.000.000đ doanh số cá nhân). | F35: 1 | G35: Truy cập trang dashboard | I35: Hệ thống hiển thị trang Dashboard chỉ với các thông tin của nhanvien Không hiển thị các widget tổng quan của Admin (như "Tổng doanh thu toàn hệ thống") | K35: Blocked | L35: Lý Sơn Yến Ngọc
C40: F2_03 | D40: Lọc dữ liệu theo tháng | E40: Có dữ liệu trong tháng 10 | F40: 1 | G40: Truy cập trang dashboard | I40: Hiển thị thống kê trong tháng 10 | K40: Blocked | L40: Lý Sơn Yến Ngọc
F41: 2 | G41: Click vào bộ lộc tháng | H41: Tháng 10
F42: 3 | G42: Xem tất cả đơn hàng
F43: 4 | G43: chọn tháng
F44: 5 | G44: Click vào lọc
C45: F2_04 | D45: Lọc dữ liệu theo 7 ngày gần nhất | E45: Có dữ liệu trong 7 ngày gần nhất | F45: 1 | G45: Click vào bộ lọc doanh thu 7 ngày gần đây | I45: Hiển thị thống kê theo bộ lọc 7 ngày gần đây | K45: Passed | L45: Lý Sơn Yến Ngọc
C50: F2_05 | D50: Lọc dữ liệu theo ngày | E50: Có dữ liệu từ ngày 6/10/2055 - 10/10/2025 | F50: 1 | G50: Click vào bộ lọc ngày | I50: Hiển thị thống kê theo bộ lọc ngày | K50: Blocked | L50: Lý Sơn Yến Ngọc
F51: 2 | G51: Chọn ngày bắt đầu | H51: 45818
F52: 3 | G52: Chọn ngày kết thúc | H52: 45940
F53: 4 | G53: Click nút lọc
C55: F2_06 | D55: Làm mới dữ liệu dashboard | E55: Có nút refresh dữ liệu | F55: 1 | G55: Quan sát thời gian cập nhật cuối | I55: Hiển thị "last update: time" hiển thị thời gian hiện tại , icon xoay hiển thị loading, dữ liệu được cập nhật mới nhất | K55: Blocked | L55: Lý Sơn Yến Ngọc
F56: 2 | G56: Click nút "Refresh" (của chome)
F57: 3 | G57: Chờ dữ liệu tải
F58: 4 | G58: Kiểm tra thời gian cập nhật
C60: F2_07 | D60: Xuất báo cáo dashboard | E60: Admin đã đăng nhập đang ở dashboard | F60: 1 | G60: Click nút "Export báo cáo" | I60: Xuất file pdf thành công và có thể mở file lên được | K60: Blocked | L60: Lý Sơn Yến Ngọc
...

Sheet Test Cases  CUS
D2: MINH NHỰT
D4: Sau khi hoàn thành test requirement thì đưa ra các trường hợp test case tương ứng với test requirement mà mình đã làm
B9: Test Cases for 'Quản lý bán hàng online' function
L10: Execute Testing - Version1.0
B11: No. | C11: Test Requirement ID | D11: Test Case ID | E11: Test Objective | F11: Pre-conditions | G11: Step # | H11: Step Action | I11: Test Data | J11: Expected Result | K11: Notes | L11: Result | M11: By tester | N11: Note
B12: Functional TCs
B13: 1 | C13: F1.1 | D13: F1_00 | E13: Kiểm tra giao diện đăng nhập customer | F13: Vào được trang đăng nhập | G13: 1 | H13: Mở trang đăng nhập | J13: Giao diện được thiết kế và hiển thị đúng theo yêu cầu | L13: Passed | M13: Lý Sơn Yến Ngọc
G14: 2 | H14: Check giao diện theo form
G15: 3 | H15: Check giao diện theo checklist
C17: Back | D17: F1.1_01 | E17: Đăng nhập thành công với tài khoản và mật khẩu đúng | F17: Tài khoản đã được đăng ký trước đó | G17: 1 | H17: Mở trang đăng nhập | J17: Đăng nhập thành công chuyển hướng đến trang home (https://localhost:7011/) | L17: Passed | M17: Lý Sơn Yến Ngọc
G18: 2 | H18: Nhập email đăng nhập hợp lệ | I18: test@gmail.com
G19: 3 | H19: Nhập mật khẩu hợp lệ | I19: Nhut@2005
G20: 4 | H20: Click nút đăng nhập
D21: F1.1_02 | E21: Đăng nhập thất bại với email chưa được đăng ký | F21: Không có | G21: 1 | H21: Mở trang đăng nhập | J21: Hiển thị thông báo "Email hoặc mật khẩu không đúng" | L21: Passed | M21: Lý Sơn Yến Ngọc
G22: 2 | H22: Nhập email đăng nhập không tồn tại | I22: mhnhwt@gmail.com
G23: 3 | H23: Nhập mật khẩu bất kỳ | I23: 123456
G24: 4 | H24: Click nút đăng nhập
D25: F1.1_03 | E25: Đăng nhập thất bại với mật khẩu sai | F25: Tài khoản đã tồn tại | G25: 1 | H25: Mở trang đăng nhập | J25: Hiển thị thông báo "Email hoặc mật khẩu không đúng" | L25: Passed | M25: Lý Sơn Yến Ngọc
G26: 2 | H26: Nhập email đăng nhập hợp lệ | I26: test@gmail.com
G27: 3 | H27: Nhập mật khẩu hợp lệ | I27: nhut123
G28: 4 | H28: Click nút đăng nhập
D29: F1.1_04 | E29: Đăng nhập thất bại với trường Emai bỏ trống | F29: Không có | G29: 1 | H29: Mở trang đăng nhập | J29: Hiển thị thông báo "vui lòng nhập email !" | L29: Passed | M29: Lý Sơn Yến Ngọc
G30: 2 | H30: Để trống email đăng nhập
G31: 3 | H31: Nhập mật khẩu bất kỳ | I31: nhut123
G32: 4 | H32: Click nút đăng nhập
D33: F1.1_05 | E33: Đăng nhập thất bại với trường mật khẩu bỏ trống | F33: Không có | G33: 1 | H33: Mở trang đăng nhập | J33: Hiển thị thông báo vui " lòng nhập mật khẩu" | L33: Passed | M33: Lý Sơn Yến Ngọc
G34: 2 | H34: Nhập emai đã được đăng ký | I34: test@gmail.com
G35: 3 | H35: Bỏ trống mật khẩu
G36: 4 | H36: Click nút đăng nhập
D37: F1.1_06 | E37: Đăng nhập thất bại với trường email và mật khẩu bỏ trống | F37: Không có | G37: 1 | H37: Mở trang đăng nhập | J37: Hiển thị 2 thông báo " Vui lòng nhập email " và "Vui lòng nhập mật khẩu" | L37: Passed | M37: Lý Sơn Yến Ngọc
G38: 2 | H38: Bỏ trống emai
G39: 3 | H39: Bỏ trống mật khẩu
G40: 4 | H40: Click nút đăng nhập
B41: 2 | C41: F1.2 | D41: F1.2_01 | E41: Đăng ký thành công với thông tin hợp lệ | F41: Không có | G41: 1 | H41: Truy cập trang đăng ký | J41: Đăng ký thành công, chuyển hướng đến trang chủ | L41: Passed | M41: Lý Sơn Yến Ngọc
G42: 2 | H42: Nhập họ | I42: Hoàng
G43: 3 | H43: Nhập tên | I43: Nhựt
G44: 4 | H44: Nhập email | I44: test01@gmail.com
G45: 5 | H45: Nhập số điện thoại | I45: 978782783
G46: 6 | H46: Nhập mật khẩu | I46: Nhut@2005
G47: 7 | H47: Xác nhận mât khẩu | I47: Nhut@2005
...

Sheet Checklist GUI
A1: Test Cases for 'Quản lý bán hàng online' function
K2: Execute Testing - Version1.0
A3: No. | B3: Test Requirement ID | C3: Test Case ID | D3: Test Objective | E3: Pre-conditions | F3: Step # | G3: Step Action | H3: Test Data | I3: Expected Result | J3: Passed | K3: Result | L3: By tester | M3: Note
A4: Functional TCs
A5: 1 | B5: F1 | C5: F1_00 | D5: Kiểm tra giao diện đăng nhập admin | E5: Vào được trang đăng nhập | F5: 1 | G5: Mở trang đăng nhập | I5: Giao diện được thiết kế đúng theo yêu cầu | J5: Passed | K5: Passed | L5: Lý Sơn Yến Ngọc
F6: 2 | G6: Check giao diện theo form | H6: form đăng nhập
F7: 3 | G7: Check giao diện theo checklist gui | H7: checklist gui
B10: BACK | C10: F1_01 | D10: Đăng nhập thành công | E10: Tài khoản đã được đăng ký trước đó | F10: 1 | G10: Mở trang đăng nhập | I10: Đăng nhập thành công chuyển hướng đến trang Admin | K10: Passed | L10: Lý Sơn Yến Ngọc
F11: 2 | G11: Nhập tên đăng nhập hợp lệ | H11: admin1
F12: 3 | G12: Nhập mật khẩu hợp lệ | H12: 123
F13: 4 | G13: Click nút đăng nhập
C15: F1_02 | D15: Đăng nhập thất bại | E15: Không có | F15: 1 | G15: Mở trang đăng nhập | I15: Hiển thị thông báo tên đăng nhập hoặc mật khẩu không đúng | K15: Passed | L15: Lý Sơn Yến Ngọc
F16: 2 | G16: Nhập tên đăng nhập không tồn tại | H16: admin2
F17: 3 | G17: Nhập mật khẩu bất kỳ | H17: 123
F18: 4 | G18: Click nút đăng nhập
C20: F1_03 | D20: Đăng nhập thất bại với mật khẩu sai | E20: Tài khoản đã tồn tại | F20: 1 | G20: Mở trang đăng nhập | I20: Hiển thị thông báo tên đăng nhập hoặc mật khẩu không đúng | K20: Passed | L20: Lý Sơn Yến Ngọc
F21: 2 | G21: Nhập tên đăng nhập hợp lệ | H21: admin1
F22: 3 | G22: Nhập mật khẩu sai | H22: 456
F23: 4 | G23: Click nút đăng nhập
C25: F1_04 | D25: Đăng nhập với trường bỏ trống | E25: Không có | F25: 1 | G25: Mở trang đăng nhập | I25: Hiển thị thông báo vui lòng nhập email và vui lòng nhập mật khẩu | K25: Passed | L25: Lý Sơn Yến Ngọc
F26: 2 | G26: Để trống tên đăng nhập
F27: 3 | G27: Để trống mật khẩu
F28: 4 | G28: Click nút đăng nhập
A30: 3 | B30: F2 | C30: F2_01 | D30: Kiểm tra hiển thị dashboard chính xác với vai trò Admin | E30: Hệ thống đã có dữ liệu (ví dụ: 100 đơn hàng, 50.000.000đ tổng doanh thu) | F30: 1 | G30: Truy cập trang dashboard | I30: Hệ thống hiển thị trang Dashboard với đầy đủ các thông tin tổng quan của toàn hệ thống: | K30: Passed | L30: Lý Sơn Yến Ngọc
B35: BACK | C35: F2_02 | D35: Kiểm tra hiển thị dashboard chính xác với vai trò Nhân viên Bán hàng | E35: Có dữ liệu riêng (ví dụ: 10 đơn hàng đã xử lý, 5.000.000đ doanh số cá nhân). | F35: 1 | G35: Truy cập trang dashboard | I35: Hệ thống hiển thị trang Dashboard chỉ với các thông tin của nhanvien Không hiển thị các widget tổng quan của Admin (như "Tổng doanh thu toàn hệ thống") | K35: Blocked | L35: Lý Sơn Yến Ngọc
C40: F2_03 | D40: Lọc dữ liệu theo tháng | E40: Có dữ liệu trong tháng 10 | F40: 1 | G40: Truy cập trang dashboard | I40: Hiển thị thống kê trong tháng 10 | K40: Blocked | L40: Lý Sơn Yến Ngọc
F41: 2 | G41: Click vào bộ lộc tháng | H41: Tháng 10
F42: 3 | G42: Xem tất cả đơn hàng
F43: 4 | G43: chọn tháng
F44: 5 | G44: Click vào lọc
C45: F2_04 | D45: Lọc dữ liệu theo 7 ngày gần nhất | E45: Có dữ liệu trong 7 ngày gần nhất | F45: 1 | G45: Click vào bộ lọc doanh thu 7 ngày gần đây | I45: Hiển thị thống kê theo bộ lọc 7 ngày gần đây | K45: Passed | L45: Lý Sơn Yến Ngọc
C50: F2_05 | D50: Lọc dữ liệu theo ngày | E50: Có dữ liệu từ ngày 6/10/2055 - 10/10/2025 | F50: 1 | G50: Click vào bộ lọc ngày | I50: Hiển thị thống kê theo bộ lọc ngày | K50: Blocked | L50: Lý Sơn Yến Ngọc
F51: 2 | G51: Chọn ngày bắt đầu | H51: 45818
F52: 3 | G52: Chọn ngày kết thúc | H52: 45940
F53: 4 | G53: Click nút lọc
C55: F2_06 | D55: Làm mới dữ liệu dashboard | E55: Có nút refresh dữ liệu | F55: 1 | G55: Quan sát thời gian cập nhật cuối | I55: Hiển thị "last update: time" hiển thị thời gian hiện tại , icon xoay hiển thị loading, dữ liệu được cập nhật mới nhất | K55: Blocked | L55: Lý Sơn Yến Ngọc
F56: 2 | G56: Click nút "Refresh" (của chome)
F57: 3 | G57: Chờ dữ liệu tải
F58: 4 | G58: Kiểm tra thời gian cập nhật
C60: F2_07 | D60: Xuất báo cáo dashboard | E60: Admin đã đăng nhập đang ở dashboard | F60: 1 | G60: Click nút "Export báo cáo" | I60: Xuất file pdf thành công và có thể mở file lên được | K60: Blocked | L60: Lý Sơn Yến Ngọc
...

Sheet GUI 1_Ngọc
B2: Nhiệm vụ: Test giao diện GUI của web admin (dựa vào cách trình bày của sheet GUI-APPLY LEAVE)
B5: Các phần test: Đăng ký - Đăng nhập - Quản lý sản phẩm - Quản lý danh mục - Quản lý màu sắc - Quản lý đơn hàng - Quản lý khách hàng (Test các giao diện thêm - xóa sửa)
B8: Bên dưới là bảng mẫu để làm - Khi làm kèm theo hình ảnh giao diện mà mình test bên cạnh bảng
B11: Mỗi hình tương ứng với mỗi bảng - bao nhiêu hình thì bấy nhiêu bảng - trình bày theo chiều ngang hoặc dọc
B17: ĐĂNG NHẬP ADMIN | D17: BACK REQUIRE | E17: BACK TC
B18: NO. | C18: INPUT FIELD | D18: DESCRIPTION | E18: CONSTRAINTS
B19: 1 | C19: Tên đăng nhập | D19: Trường đăng nhập tên tài khoản admin | E19: Bắt buộc nhập Không được để trống Không chỉ chứa khoảng trắng Độ dài tối thiểu: 3 ký tự (hoặc theo rule hệ thống) Độ dài tối đa: 255 ký tự Không cho phép ký tự đặc biệt (nếu hệ thống cấm) Tên đăng nhập phải tồn tại trong hệ thống Tự động trim khoảng trắng đầu/cuối
B20: 2 | C20: Mật khẩu | D20: Trường nhập mật khẩu đăng nhập admin | E20: Bắt buộc nhập Không được để trống Không chỉ chứa khoảng trắng Độ dài tối thiểu: 6 ký tự (hoặc theo rule hệ thống) Độ dài tối đa: 255 ký tự Mật khẩu phải khớp với tài khoản
B21: 3 | C21: Button "Đăng nhập" | D21: Nút submit form để thực hiện đăng nhập | E21: Chỉ active khi Tên đăng nhập và Mật khẩu hợp lệ Khi click: hiển thị loading / disable nút Validate lại toàn bộ dữ liệu ở backend Nếu thành công: chuyển về trang Dashboard Nếu thất bại: hiển thị thông báo lỗi cụ thể Không cho phép click nhiều lần liên tục
B22: 4 | C22: Form Validation | D22: Xác thực toàn bộ form trước khi submit | E22: Validate realtime khi người dùng nhập/rời field Hiển thị thông báo lỗi ngay bên dưới field có lỗi Không cho phép submit khi còn lỗi Thông báo lỗi rõ ràng, dễ hiểu để người dùng biết cách sửa
B23: 5 | C23: Permission check | D23: Kiểm tra quyền truy cập trang đăng nhập admin | E23: Chỉ user có quyền “Admin” mới đăng nhập thành công User không có quyền → hiển thị lỗi hoặc redirect phù hợp Nếu đã đăng nhập và truy cập lại trang login → chuyển về Dashboard Kiểm tra quyền cả ở frontend và backend
B29: ĐĂNG KÝ ADMIN | D29: BACK REQUIRE | E29: BACK TC
B30: NO. | C30: INPUT FIELD | D30: DESCRIPTION | E30: CONSTRAINTS
B31: 1 | C31: Họ và tên | D31: Trường nhập họ và tên của admin | E31: Bắt buộc nhập Không được để trống Không chứa ký tự đặc biệt hoặc số Độ dài tối thiểu: 3 ký tự Độ dài tối đa: 255 ký tự
B32: 2 | C32: Tên đăng nhập | D32: Trường nhập tên đăng nhập | E32: Bắt buộc nhập Không được để trống Không chứa ký tự đặc biệt Độ dài tối thiểu: 3 ký tự Độ dài tối đa: 50 ký tự Tên đăng nhập phải là duy nhất trong hệ thống
B33: 3 | C33: CMND/CCCD | D33: Trường nhập số CMDN hoặc số CCCD | E33: Bắt buộc nhập Không được để trống Chỉ chứa chữ số Độ dài: 9 hoặc 12 chữ số Không được chứa ký tự chữ hoặc ký tự đặc biệt
B34: 4 | C34: Vai trò | D34: Dropdown chọn vai trò | E34: Bắt buộc chọn Không được để trống Phải chọn 1 trong các giá trị có sẵ
B35: 5 | C35: Mật khẩu | D35: Trường nhập mật khẩu | E35: Bắt buộc nhập Không được để trống Độ dài tối thiểu: 6 ký tự Độ dài tối đa: 50 ký tự Khuyến khích chứa chữ hoa, chữ thường, số
B36: 6 | C36: Xác nhận mật khẩu | D36: Trường nhập lại mật khẩu để xác nhận | E36: Bắt buộc nhập Không được để trống Phải trùng khớp với mật khẩu đã nhập ở trường “Mật khẩu”
B42: THÊM SẢN PHẨM MỚI | D42: BACK REQUIRE | E42: BACK TC
B43: NO. | C43: INPUT FIELD | D43: DESCRIPTION | E43: CONSTRAINTS
B44: 1 | C44: Tên sản phẩm | D44: Trường nhập tên sản phẩm | E44: Bắt buộc nhập. Không được để trống Không được chứa ký tự đặc biệt Độ dài tối thiểu: 3 ký tự Độ dài tối đa: 255 ký tự Tên sản phẩm phải là duy nhất trong hệ thống
B45: 2 | C45: Danh mục | D45: Dropdown chọn danh mục sản phẩm | E45: Bắt buộc chọn từ danh sách Chỉ hiển thị các danh mục đang có trong hệ thống Nếu chưa có danh mục nào thì hiển thị thông báo tạo danh mục trước
B46: 3 | C46: Giá | D46: Trường nhập giá bán sản phẩm | E46: Bắt buộc nhập Chỉ nhập số nguyên dương hoặc 0 Giá trị tối thiểu: 0 Giá trị tối đa: 999.999.999 Không cho phép nhập chữ hoặc ký tự đặc biệt Tự động format hiển thị theo định dạng tiền (VD: 1,000,000 VNĐ)
B47: 4 | C47: Số lượng tồn | D47: Trường nhập số lượng tồn kho ban đầu | E47: Bắt buộc nhập Chỉ nhập số nguyên dương hoặc 0 Giá trị tối thiểu: 0 Giá trị tối đa: 999.999.999 Không cho phép nhập chữ hoặc ký tự đặc biệt
B48: 5 | C48: Chương trình giảm giá | D48: Dropdown chọn chương trình giảm giá áp dụng | E48: Không bắt buộc Chỉ hiển thị các chương trình giảm giá đang active và còn hạn Nếu chọn chương trình giảm giá, giá hiển thị trên web sẽ được tính lại theo chương trình Một sản phẩm chỉ được áp dụng tối đa 1 chương trình giảm giá Chương trình giảm giá được quản lý trong module Quản lý chương trình giảm giá
B49: 6 | C49: Mô tả ngắn | D49: Trường nhập mô tả ngắn gọn về sản phẩm | E49: Không bắt buộc Độ dài tối đa: 500 ký tự Mô tả ngắn sẽ hiển thị tren trang danh sách sản phẩm Không cho phép HTML tags để tránh XSS Có thể chứa emoji
B50: 7 | C50: Mô tả chi tiết | D50: Trường nhập mô tả chi tiết đầy đủ về sản phẩm | E50: Không bắt buộc Độ dài tối đa: 5000 ký tự Mô tả ngắn sẽ hiển thị trên trang chi tiết sản phẩm Không cho phép HTML tags để tránh XSS Có thể chứa emoji Có thể hỗ trợ text editor để format text (bold, italic…)
B51: 8 | C51: Chọn màu | D51: Dropdown chọn màu sắc có sẵn cho sản phẩm | E51: Bắt buộc chọn ít nhất 1 màu Chỉ hiển thị các màu đã được thiết lập trong module quản lý màu sắc Có thể chọn nhiều màu khác nhau cho 1 sản phẩm Mỗi màu phải có ít nhất 1 hình ảnh đi kèm Không được chọn trùng màu trong cùng 1 sản phẩm
B52: 9 | C52: Nút X | D52: Nút xóa màu đã chọn | E52: Chỉ hiển thị khi đã chọn màu Click để xóa màu và các hình ảnh liên quan Nếu chỉ còn 1 màu duy nhất không cho phép xóa Xóa màu sẽ xóa luôn tất cả hình ảnh upload cho màu đó
B53: 10 | C53: Image Upload | D53: Khu vực upload ảnh cho từng màu sắc | E53: Bắt buộc upload ít nhất 1 hình cho mỗi màu Chấp nhận định dạng: PNG, JPG, JPEG Kích thước file tối đa: 10Mb/ảnh Khuyến nghị kích thước ảnh: 800x800px Có thể upload tối đa 10 ảnh cho 1 màu Ảnh đầu tiên sẽ là ảnh đại diện chính Hệ thống tự động resize và optimize ảnh khi lưu
B54: 11 | C54: Button "Thêm màu sắc" | D54: Nút thêm thêm một màu sắc mới cho sản phẩm | E54: Chỉ active khi màu hiện tại đã được chọn và có ít nhất 1 hình ảnh Click để thêm row mới chọn màu và upload ảnh Tối đã có thể thêm 10 màu cho 1 sản phẩm Mỗi màu mới thêm phải khác với các màu đã chọn trước đó
B55: 12 | C55: Button "Thêm sản phẩm" | D55: Nút submit form để lưu sản phẩm mới vào hệ thống | E55: Chỉ active khi tất cả các trường bắt buộc đã nhập hợp lệ: + Tên sản phẩm đã nhập + Danh mục đã chọn + Giá đã nhập hợp lệ + Số lượng tồn đã nhập + Ít nhất 1 màu đã chọn + Mỗi màu có ít nhất 1 hình ảnh Hiển thị loading indicator Validate lại tất cả dữ liệu ở backenđ Nếu thành công: Chuyển về trang danh sách sản phẩm Nếu lỗi: Hiển thị thông báo lỗi cụ thể Không cho phép submit nhiều lần
... B57: 14 | C57: Permission check | D57: Kiểm tra quyền thêm sản phẩm | E57: User phải có quyền "Thêm sản phẩm" mới được truy cập trang này Nếu không có quyền, rediret về trang dashboard với thông báo lỗi Kiểm tra quyền cả ở frontend và backend
B63: CHỈNH SỬA SẢN PHẨM | D63: BACK REQUIRE | E63: BACK TC
B64: NO. | C64: INPUT FIELD | D64: DESCRIPTION | E64: CONSTRAINTS
B65: 1 | C65: Tên sản phẩm | D65: Trường nhập tên sản phẩm | E65: Bắt buộc nhập Không được để trống Không được chứa ký tự đặc biệt Độ dài tối thiểu: 3 ký tự Độ dài tối đa: 255 ký tự Tên sản phẩm phải là duy nhất trong hệ thống
B66: =B65+1 -> 2 | C66: Danh mục | D66: Dropdown chọn danh mục sản phẩm | E66: Bắt buộc chọn từ danh sách Chỉ hiển thị các danh mục đang có trong hệ thống Nếu chưa có danh mục nào thì hiển thị thông báo tạo danh mục trước
B67: =B66+1 -> 3 | C67: Giá | D67: Trường nhập giá bán sản phẩm | E67: Bắt buộc nhập Chỉ nhập số nguyên dương hoặc 0 Giá trị tối thiểu: 0 Giá trị tối đa: 999.999.999 Không cho phép nhập chữ hoặc ký tự đặc biệt Tự động format hiển thị theo định dạng tiền tệ
B68: =B67+1 -> 4 | C68: Số lượng tồn kho | D68: Trường nhập số lượng tồn kho ban đầu | E68: Bắt buộc nhập Chỉ nhập số nguyên dương hoặc 0 Giá trị tối thiểu: 0 Giá trị tối đa: 999.999.999 Không cho phép nhập chữ hoặc ký tự đặc biệt
...

Sheet GUI2_Quân
B2: Nhiệm vụ: Test giao diện GUI của web customer và web admin (dựa vào cách trình bày của sheet GUI-APPLY LEAVE)
B5: Các phần test: Web Customer: Trang chủ - Trang đăng nhập - Trang đăng ký - Trang sản phẩm
B8: Các phần test: Web Admin: Quản lý gói thành viên - Quản lý coupon - Quản lý bảo hành (giao diện thêm - sửa xóa) - Thông tin cá nhân
B11: Bên dưới là bảng mẫu để làm - Khi làm kèm theo hình ảnh giao diện mà mình test bên cạnh bảng
B14: Mỗi hình tương ứng với mỗi bảng - bao nhiêu hình thì bấy nhiêu bảng - trình bày theo chiều ngang hoặc dọc
B21: ĐĂNG NHẬP CUSTOMER | D21: BACK REQUIRE | E21: BACK TC
B22: NO. | C22: INPUT FIELD | D22: DESCRIPTION | E22: CONSTRAINTS
B23: 1 | C23: Email | D23: Trường nhập email của người dùng | E23: - Bắt buộc nhập - Không được để trống - Phải đúng định dạng email (VD: tên@domain.com) - Không cho phép ký tự đặc biệt hoặc khoảng trắng đầu/cuối - Độ dài tối đa: 254 ký tự - Không hiển thị lỗi chi tiết để tránh lộ thông tin
B24: 2 | C24: Mật khẩu | D24: Trường nhập mật khẩu | E24: - Bắt buộc nhập - Không được để trống - Độ dài tối thiểu: 8 ký tự - Độ dài tối đa: 128 ký tự - Không cho phép khoảng trắng đầu/cuối - Không hiển thị mật khẩu dạng plaintext
B25: 3 | C25: Ghi nhớ đăng nhập | D25: Checkbox lưu trạng thái đăng nhập | E25: - Không bắt buộc - Nếu chọn, lưu token tạm thời, không lưu mật khẩu - Phải có cảnh báo “Không nên sử dụng trên máy công cộng”
B26: 4 | C26: Button “Đăng nhập” | D26: Nút gửi form đăng nhập | E26: - Chỉ active khi Email và Mật khẩu hợp lệ - Có trạng thái loading khi gửi - Không cho click nhiều lần - Validate lại ở backend - Nếu thành công: chuyển qua trang chủ - Nếu lỗi: hiển thị “Email hoặc mật khẩu không đúng”
B27: 5 | C27: Link “Quên mật khẩu?” | D27: Liên kết đến trang khôi phục mật khẩu | E27: - Không bắt buộc - Phải mở form nhập email và gửi link khôi phục - Không tiết lộ email có tồn tại hay không
B28: 6 | C28: Link “Tạo tài khoản mới” | D28: Liên kết sang trang đăng ký tài khoản | E28: - Không bắt buộc - Chuyển hướng sang trang đăng ký - Nếu đã đăng nhập, tự động về dashboard
B29: 7 | C29: Chọn phương thức đăng nhập | D29: Cho phép người dùng chọn đăng nhập bằng Email / Số điện thoại / Tên người dùng. | E29: Tối đa 1 trường được nhập. Không bắt buộc nếu auto detect.
B30: 8 | C30: Tùy chọn “Ẩn / Hiện” mật khẩu | D30: Biểu tượng con mắt để xem hoặc ẩn mật khẩu. | E30: Không bắt buộc.
B31: 9 | C31: Cảnh báo khi dùng mật khẩu yếu | D31: Kiểm tra độ mạnh mật khẩu khi nhập. | E31: Thông báo realtime (Yếu / Trung bình / Mạnh).
B32: 10 | C32: Gợi ý đổi mật khẩu định kỳ | D32: Nhắc nhở đổi mật khẩu sau 90 ngày. | E32: Không bắt buộc, tùy chọn trong cài đặt tài khoản.
B33: 11 | C33: Đăng nhập bằng Google / Facebook (Button) | D33: Cho phép đăng nhập nhanh bằng mạng xã hội | E33: • Không bắt buộc • Tích hợp OAuth 2.0 • Khi thành công sẽ tự động tạo tài khoản nếu chưa có
B34: 12 | C34: Hiển thị logo + tên thương hiệu | D34: Gắn logo website trong form login để tăng độ tin cậy. | E34: Không bắt buộc, tùy chỉnh giao diện.
... B40: 18 | C40: Banner ưu đãi / khuyến mãi nhỏ | D40: Gợi ý đăng ký tài khoản để nhận ưu đãi | E40: • Không bắt buộc • Nội dung có thể thay đổi theo chiến dịch marketing
B43: ĐĂNG KÝ CUSTOMER | D43: BACK REQUIRE | E43: BACK TC
B44: NO. | C44: INPUT FIELD | D44: DESCRIPTION | E44: CONSTRAINTS
B45: 1 | C45: Họ | D45: Trường nhập họ của người dùng | E45: - Bắt buộc nhập. Không được để trống. Không chứa số hoặc ký tự đặc biệt. Độ dài tối đa: 50 ký tự.
B46: 2 | C46: Tên | D46: Trường nhập tên người dùng | E46: - Bắt buộc nhập. Không được để trống. Không chứa ký tự đặc biệt hoặc số. Độ dài tối đa: 50 ký tự.
B47: 3 | C47: Email | D47: Trường nhập email người dùng | E47: - Bắt buộc nhập. Phải đúng định dạng tên@domain.com. Không có khoảng trắng hoặc ký tự lạ. Độ dài tối đa 254 ký tự. Email phải là duy nhất trong hệ thống.
B48: 4 | C48: Số điện thoại | D48: Trường nhập số điện thoại của người dùng | E48: - Bắt buộc nhập. Chỉ chấp nhận ký tự số (0–9). Độ dài: 9–11 ký tự. Không cho phép ký tự chữ hoặc dấu.
B49: 5 | C49: Mật khẩu | D49: Trường nhập mật khẩu đăng ký | E49: - Bắt buộc nhập. Tối thiểu 6 ký tự (nên 8). Tối đa 128 ký tự. Không có khoảng trắng đầu/cuối. Nên có 1 chữ hoa, 1 chữ thường, 1 số. Không hiển thị plaintext.
B50: 6 | C50: Xác nhận mật khẩu | D50: Trường nhập lại mật khẩu để xác thực | E50: - Bắt buộc nhập. Phải trùng khớp hoàn toàn với ô “Mật khẩu”. Không có khoảng trắng.
B51: 7 | C51: Checkbox “Tôi đồng ý với Điều khoản & Chính sách bảo mật”” | D51: Xác nhận điều khoản và chính sách bảo mật | E51: - Bắt buộc chọn trước khi nhấn “Đăng ký”. Liên kết “Điều khoản…” phải mở được trang quy định.
B52: 8 | C52: Button “Đăng ký” | D52: Nút gửi form tạo tài khoản | E52: - Chỉ được active khi toàn bộ trường hợp lệ & checkbox được chọn. Có trạng thái loading khi gửi. Không cho phép click nhiều lần.
B53: 9 | C53: Link “Đăng nhập ngay” | D53: Dẫn sang trang đăng nhập cho người đã có tài khoản | E53: - Không bắt buộc. Khi người dùng đã đăng nhập → nên redirect sang dashboard.
B54: 10 | C54: Họ và tên | D54: Trường nhập họ và tên đầy đủ của người dùng. Dùng để thay thế hai trường riêng biệt “Họ” và “Tên”. | E54: Bắt buộc nhập. Không được để trống. Không chứa ký tự đặc biệt hoặc số. Độ dài tối đa 100 ký tự.
B55: 11 | C55: Tên hiển thị (Username / Display Name) | D55: Tên hiển thị công khai của người dùng trong hệ thống. | E55: Bắt buộc nhập. Độ dài tối đa 50 ký tự. Không chứa ký tự đặc biệt, không khoảng trắng đầu/cuối.
B56: 12 | C56: Địa chỉ nhận hàng | D56: Nhập địa chỉ giao hàng chi tiết (số nhà, đường, phường/xã, quận/huyện, tỉnh/thành) | E56: Bắt buộc nhập. Cho phép nhập tối đa 255 ký tự. Có thể hỗ trợ gợi ý tự động địa chỉ.
... B63: 19 | C63: Liên kết đăng ký nhanh (Google / Facebook / Apple) | D63: Cho phép người dùng đăng ký nhanh qua tài khoản mạng xã hội. | E63: Không bắt buộc. Khi người dùng chọn liên kết này, hệ thống tự động lấy email xác minh hợp lệ.
B68: THÊM GÓI THÀNH VIÊN | D68: BACK REQUIRE | E68: BACK TC
B69: NO. | C69: INPUT FIELD | D69: DESCRIPTION | E69: CONSTRAINTS
B70: 1 | C70: Tên gói thành viên | D70: Trường nhập tên gói (ví dụ: Vàng, Bạc) | E70: - Bắt buộc nhập - Không được để trống - Không chứa chỉ toàn khoảng trắng - Không chứa ký tự đặc biệt nghi vấn (<>/;--…) — chỉ cho phép chữ, số, dấu gạch, dấu cách - Độ dài tối thiểu: 3 ký tự - Độ dài tối đa: 100 ký tự - Tên gói phải là duy nhất trong hệ thống - Loại bỏ khoảng trắng đầu/cuối trước khi lưu - Hiển thị lỗi: Vui lòng nhập tên gói khi rỗng - Hiển thị lỗi: Tên gói đã tồn tại khi trùng (không tiết lộ thông tin nhạy cảm)
B71: 2 | C71: Mô tả | D71: Trường textarea mô tả chi tiết gói | E71: - Không bắt buộc - Độ dài tối đa: 1000 ký tự (hoặc config 5000 tuỳ hệ thống) - Không cho phép HTML tags chưa lọc để tránh XSS — escape hoặc sanitize trước khi hiển thị - Có thể chứa emoji - Hiển thị lỗi: Mô tả quá dài (tối đa 1000 ký tự) nếu vượt
B72: 3 | C72: Phần trăm giảm giá (%) | D72: Trường nhập phần trăm chiết khấu áp dụng cho gói | E72: - Bắt buộc nhập (nếu gói có giảm giá) hoặc không bắt buộc tuỳ chính sách - Chỉ nhập số (số nguyên hoặc hỗ trợ 1–2 chữ số thập phân tuỳ yêu cầu) - Giá trị tối thiểu: 0 - Giá trị tối đa: 100 - Không cho phép ký tự chữ hoặc ký tự đặc biệt khác - Tự validate boundary ở frontend và backend - Hiển thị lỗi: Phần trăm giảm giá phải là số từ 0 đến 100 khi vượt giới hạn hoặc không phải số
...

Sheet Test Case GUI2_Quân
A1: TEST CASE GUI - TRANG ĐĂNG NHẬP
A2: TestCaseID | B2: Nhóm GUI | C2: Mô tả chi tiết | D2: Điều kiện tiên quyết | E2: Các bước thực hiện | F2: Kết quả mong đợi | G2: Kết quả thực tế | H2: Trạng thái | I2: Test Priority
A3: TC_GUI_LOGIN_001 | B3: Layout & Bố cục | C3: Form đăng nhập hiển thị căn giữa trang theo chiều ngang và dọc | D3: Truy cập trang đăng nhập trên màn hình desktop (1920x1080) | E3: 1. Truy cập trình duyệt 2. Truy cập đường dẫn : https://localhost:7011/Customer/Login | F3: Form đăng nhập được căn giữa màn hình cả chiều ngang lẫn chiều dọc; Nền trang màu xám nhạt (#F0F2F5 hoặc tương đương) | I3: High
A4: TC_GUI_LOGIN_002 | B4: Layout & Bố cục | C4: Thứ tự các phần tử trên form đúng từ trên xuống dưới | D4: Truy cập trang đăng nhập | E4: 1. Truy cập trình duyệt 2. Truy cập đường dẫn : https://localhost:7011/Customer/Login 3. Quan sát thứ tự các phần tử từ trên xuống dưới | F4: Thứ tự đúng: Icon avatar → Tiêu đề 'Đăng nhập tài khoản' → Subtitle 'Hoặc đăng ký...' → Email field → Mật khẩu field → Checkbox 'Ghi nhớ đăng nhập' → Nút 'Đăng nhập' → Link 'Quên mật khẩu?' & 'Tạo tài khoản mới' | I4: High
A5: TC_GUI_LOGIN_003 | B5: Layout & Bố cục | C5: Form có nền trắng, bo góc và đổ bóng nhẹ | D5: Truy cập trang đăng nhập | E5: 1. Truy cập trình duyệt 2. Truy cập đường dẫn : https://localhost:7011/Customer/Login 3. Quan sát form đăng nhập | F5: Form có nền trắng; Góc được bo tròn; Có shadow/đổ bóng nhẹ phân biệt với nền trang | I5: Medium
A6: TC_GUI_LOGIN_004 | B6: Layout & Bố cục | C6: Khoảng cách (padding/margin) giữa các phần tử đồng đều và hợp lý | D6: Truy cập trang đăng nhập | E6: 1. Truy cập trình duyệt 2. Truy cập đường dẫn : https://localhost:7011/Customer/Login 3. Quan sát khoảng cách giữa các phần tử | F6: Khoảng cách giữa các phần tử đồng đều; Không bị chồng lấp hoặc quá rộng; Padding bên trong form hợp lý | I6: Medium
A7: TC_GUI_LOGIN_005 | B7: Icon & Hình ảnh | C7: Icon avatar hiển thị đúng màu sắc và kích thước | D7: Truy cập trang đăng nhập | E7: 1. Truy cập trình duyệt 2. Truy cập đường dẫn : https://localhost:7011/Customer/Login 3. Quan sát icon avartar ở đầu form | F7: Icon avatar hình tròn, màu xanh dương (#3B82F6 hoặc tương đương); Icon người dùng màu trắng ở giữa; Kích thước cân đối với form | I7: Medium
A8: TC_GUI_LOGIN_006 | B8: Icon & Hình ảnh | C8: Icon khóa trong nút 'Đăng nhập' hiển thị đúng | D8: Truy cập trang đăng nhập | E8: 1. Truy cập trình duyệt 2. Truy cập đường dẫn : https://localhost:7011/Customer/Login 3. Quan sát icon bên trái nút "Đăng nhập" | F8: Icon khóa (lock) màu trắng hiển thị bên trái text 'Đăng nhập'; Kích thước icon phù hợp với chiều cao nút | I8: Low
A9: TC_GUI_LOGIN_007 | B9: Typography & Text | C9: Tiêu đề 'Đăng nhập tài khoản' hiển thị đúng font, size, màu sắc | D9: Truy cập trang đăng nhập | E9: 1. Truy cập trình duyệt 2. Truy cập đường dẫn : https://localhost:7011/Customer/Login 3. Quan sát Tiêu đề chính | F9: Tiêu đề 'Đăng nhập tài khoản' in đậm (bold); Font size lớn (~24-28px); Màu đen/tối (#1F2937 hoặc tương đương); Căn giữa | I9: High
A10: TC_GUI_LOGIN_008 | B10: Typography & Text | C10: Subtitle 'Hoặc đăng ký tài khoản mới' hiển thị đúng | D10: Truy cập trang đăng nhập | E10: 1. Truy cập trình duyệt 2. Truy cập đường dẫn : https://localhost:7011/Customer/Login 3. Quan sát dòng subtitle bên dưới tiêu đề | F10: Text 'Hoặc ' màu xám nhạt; Text 'đăng ký tài khoản mới' màu xanh dương, có underline hoặc dạng link; Căn giữa | I10: Medium
A11: TC_GUI_LOGIN_009 | B11: Typography & Text | C11: Label 'Email' và 'Mật khẩu' hiển thị đúng vị trí và kiểu chữ | D11: Truy cập trang đăng nhập | E11: 1. Truy cập trình duyệt 2. Truy cập đường dẫn : https://localhost:7011/Customer/Login 3. Quan sát label các trường nhập liệu | F11: Label 'Email' và 'Mật khẩu' nằm phía trên input tương ứng; Font size nhỏ hơn tiêu đề; Màu tối, không in đậm hoặc in đậm nhẹ; Căn trái | I11: Medium
A12: TC_GUI_LOGIN_010 | B12: Typography & Text | C12: Placeholder text trong các input field hiển thị đúng | D12: Truy cập trang đăng nhập | E12: 1. Truy cập trình duyệt 2. Truy cập đường dẫn : https://localhost:7011/Customer/Login 3. Quan sát placeholder của trường email và mật khẩu khi chưa nhập | F12: Ô Email hiển thị placeholder 'Nhập email của bạn' màu xám nhạt; Ô Mật khẩu hiển thị placeholder 'Nhập mật khẩu' màu xám nhạt; Placeholder biến mất khi bắt đầu nhập | I12: Medium
A13: TC_GUI_LOGIN_011 | B13: Input Fields | C13: Hai ô nhập Email và Mật khẩu có chiều rộng bằng nhau và đều bằng chiều rộng form | D13: Truy cập trang đăng nhập | E13: 1. Truy cập trình duyệt 2. Truy cập đường dẫn : https://localhost:7011/Customer/Login 3.So sánh chiều rộng 2 ô input với nhau và với form | F13: Hai ô input có cùng chiều rộng; Chiều rộng bằng phần nội dung của form; Viền (border) rõ ràng, màu xám nhạt | I13: High
A14: TC_GUI_LOGIN_012 | B14: Input Fields | C14: Ô input hiển thị viền highlight khi được focus (click vào) | D14: Truy cập trang đăng nhập | E14: 1. Truy cập trình duyệt 2. Truy cập đường dẫn : https://localhost:7011/Customer/Login 3. Click vào ô Email 4. Quan sát viền hightlight khi click vào | F14: Viền ô input chuyển sang màu xanh dương khi focus; Có hiệu ứng outline rõ ràng phân biệt với trạng thái bình thường | I14: Medium
... A44: TC_GUI_LOGIN_042 | B44: Accessibility | C44: Focus indicator hiển thị rõ trên tất cả các phần tử tương tác | D44: Truy cập trang đăng nhập | E44: 1. Truy cập trình duyệt 2. Truy cập đường dẫn : https://localhost:7011/Customer/Login 3. Dùng phím Tab để di chuyển qua các phần tử 4. Quan sát focus indicator | F44: Mỗi phần tử tương tác đều có focus indicator rõ ràng khi nhận focus bằng keyboard; Không có phần tử nào bị 'mất' focus (outline: none mà không có alternative) | I44: Medium
A46: TEST CASE GUI - ĐĂNG KÍ
A48: TestCaseID | B48: Nhóm GUI | C48: Mô tả chi tiết | D48: Điều kiện tiên quyết | E48: Các bước thực hiện | F48: Kết quả mong đợi | G48: Kết quả thực tế | H48: Trạng thái | I48: Test Priority
A49: TC_GUI_REG_001 | B49: Layout & Bố cục | C49: Form đăng ký hiển thị căn giữa trang theo chiều ngang | D49: Truy cập trang đăng ký trên desktop 1920x1080 | E49: 1. Truy cập trình duyệt 2. Truy cập đường dẫn : https://localhost:7011/Customer/Register 3. Quan sát vị trí form trên trang | F49: Form căn giữa màn hình theo chiều ngang; Nền trang màu xám nhạt tương phản với form trắng | I49: High
A50: TC_GUI_REG_002 | B50: Layout & Bố cục | C50: Thứ tự các phần tử trên form đúng từ trên xuống dưới | D50: Truy cập trang đăng ký | E50: 1. Truy cập trình duyệt 2. Truy cập đường dẫn : https://localhost:7011/Customer/Register 3. Quan sát thứ tự từng phần tử từ trên xuống | F50: Thứ tự đúng: Icon avatar+ → Tiêu đề 'Đăng ký tài khoản mới' → Subtitle 'Đã có tài khoản? Đăng nhập ngay' → Họ → Tên → Email → Số điện thoại → Mật khẩu → Xác nhận mật khẩu → Checkbox điều khoản → Nút 'Đăng ký' | I50: High
A51: TC_GUI_REG_003 | B51: Layout & Bố cục | C51: Form có nền trắng, bo góc và đổ bóng nhẹ | D51: Truy cập trang đăng ký | E51: 1. Truy cập trình duyệt 2. Truy cập đường dẫn : https://localhost:7011/Customer/Register 3. Quan sát card form | F51: Form nền trắng; Góc bo tròn; Có shadow phân biệt với nền trang xám | I51: Medium
A52: TC_GUI_REG_004 | B52: Layout & Bố cục | C52: Khoảng cách giữa các input field đồng đều và không bị chồng lấp | D52: Truy cập trang đăng ký | E52: 1. Truy cập trình duyệt 2. Truy cập đường dẫn : https://localhost:7011/Customer/Register 3. Quan sát khoảng cách giữa 6 trường nhập liệu | F52: Khoảng cách giữa các field đồng đều nhau; Không có field nào bị chồng lấp hoặc dính vào nhau; Padding trong form cân đối | I52: Medium
A53: TC_GUI_REG_005 | B53: Layout & Bố cục | C53: Tất cả 6 input field có cùng chiều rộng bằng chiều rộng form | D53: Truy cập trang đăng ký | E53: 1. Mở trang đăng ký 2. So sánh chiều rộng của 6 ô input: Họ, Tên, Email, SĐT, Mật khẩu, Xác nhận mật khẩu | F53: Cả 6 ô input có cùng chiều rộng; Chiều rộng bằng phần nội dung form; Không có ô nào nhỏ hơn hoặc lớn hơn | I53: High
A54: TC_GUI_REG_006 | B54: Icon & Hình ảnh | C54: Icon avatar+ (thêm người dùng) hiển thị đúng màu và kích thước | D54: Truy cập trang đăng ký | E54: 1. Truy cập trình duyệt 2. Truy cập đường dẫn : https://localhost:7011/Customer/Register 3. Quan sát icon ở đầu form | F54: Icon hình tròn màu xanh dương; Biểu tượng người dùng có dấu + màu trắng ở giữa; Kích thước cân đối với form; Khác với icon trang đăng nhập (không có dấu +) | I54: Medium
A55: TC_GUI_REG_007 | B55: Icon & Hình ảnh | C55: Icon người dùng trong nút 'Đăng ký' hiển thị đúng | D55: Truy cập trang đăng ký | E55: 1. Truy cập trình duyệt 2. Truy cập đường dẫn : https://localhost:7011/Customer/Register 3. Quan sát icon bên trái trong nút 'Đăng ký' | F55: Icon người dùng (add person) màu trắng hiển thị bên trái text 'Đăng ký'; Kích thước icon phù hợp chiều cao nút; Icon không bị vỡ hoặc mờ | I55: Low
A56: TC_GUI_REG_008 | B56: Typography & Text | C56: Tiêu đề 'Đăng ký tài khoản mới' hiển thị đúng font, size, màu | D56: Truy cập trang đăng ký | E56: 1. Truy cập trình duyệt 2. Truy cập đường dẫn : https://localhost:7011/Customer/Register 3. Quan sát tiêu đề chính | F56: Tiêu đề 'Đăng ký tài khoản mới' in đậm (bold); Font size lớn (~24-28px); Màu đen/tối; Căn giữa | I56: High
A57: TC_GUI_REG_009 | B57: Typography & Text | C57: Subtitle 'Đã có tài khoản? Đăng nhập ngay' hiển thị đúng | D57: Truy cập trang đăng ký | E57: 1. Truy cập trình duyệt 2. Truy cập đường dẫn : https://localhost:7011/Customer/Register 3. Quan sát dòng subtitle dưới tiêu đề | F57: Text 'Đã có tài khoản? ' màu xám; Text 'Đăng nhập ngay' màu xanh dương dạng link; Căn giữa; Font nhỏ hơn tiêu đề | I57: Medium
A58: TC_GUI_REG_010 | B58: Typography & Text | C58: Tất cả 6 label (Họ, Tên, Email, SĐT, Mật khẩu, Xác nhận mật khẩu) hiển thị đúng vị trí | D58: Truy cập trang đăng ký | E58: 1. Truy cập trình duyệt 2. Truy cập đường dẫn : https://localhost:7011/Customer/Register 3. Quan sát vị trí label của từng trường | F58: Mỗi label nằm phía trên input tương ứng; Căn trái; Font rõ ràng, màu tối; Khoảng cách giữa label và input nhất quán | I58: High
A59: TC_GUI_REG_011 | B59: Typography & Text | C59: Placeholder của từng input field hiển thị đúng nội dung | D59: Truy cập trang đăng ký | E59: 1. Truy cập trình duyệt 2. Truy cập đường dẫn : https://localhost:7011/Customer/Register 3. Quan sát placeholder trong từng ô input khi chưa nhập | F59: Họ: 'Nhập họ của bạn' Tên: 'Nhập tên của bạn' Email: 'Nhập email của bạn' SĐT: 'Nhập số điện thoại' Mật khẩu: 'Nhập mật khẩu (tối thiểu 6 ký tự)' Xác nhận: 'Nhập lại mật khẩu' Tất cả màu xám nhạt, biến mất khi nhập | I59: High
A60: TC_GUI_REG_012 | B60: Typography & Text | C60: Font chữ nhất quán trên toàn bộ trang đăng ký | D60: Truy cập trang đăng ký | E60: 1. Truy cập trình duyệt 2. Truy cập đường dẫn : https://localhost:7011/Customer/Register 3. Quan sát font của tất cả text trên trang | F60: Tất cả text dùng cùng font family; Không có font lạc nhịp; Font tải đúng, không fallback sang font mặc định | I60: Medium
... A92: TC_GUI_REG_044 | B92: Accessibility | C92: Trang đăng ký nhất quán về visual với trang đăng nhập | D92: Mở cả hai trang đăng nhập và đăng ký | E92: 1. Truy cập trình duyệt 2. Truy cập đường dẫn : https://localhost:7011/Customer/Login 3. Truy cập đường dẫn : https://localhost:7011/Customer/Register 4. So sánh visual tổng thể | F92: Hai trang dùng cùng design language; Màu sắc chủ đạo nhất quán; Font, border-radius, shadow nhất quán; Chỉ khác nhau ở nội dung, không khác về phong cách | I92: Medium
A94: Test Case GUI - Trang chủ
A95: TestCaseID | B95: Nhóm GUI | C95: Mô tả chi tiết | D95: Điều kiện tiên quyết | E95: Các bước thực hiện | F95: Kết quả mong đợi | G95: Kết quả thực tế | H95: Trạng thái | I95: Test Priority
A96: TC_GUI_HP_001 | B96: Header & Navbar | C96: Header cố định (sticky) ở đầu trang khi cuộn xuống | D96: Truy cập trang chủ, trang có nội dung dài hơn viewport | E96: 1. Truy cập trình duyệt 2. Truy cập đường dẫn : https://localhost:7011/ 3. Cuộn xuống phần sản phẩm nổi bật 4. Quan sát header | F96: Header vẫn hiển thị ở đầu trang khi cuộn; Không bị ẩn hay trượt lên; Có shadow hoặc background trắng rõ ràng khi sticky | I96: High
A97: TC_GUI_HP_002 | B97: Header & Navbar | C97: Logo 'PhoneStore' hiển thị đúng vị trí, icon và màu sắc | D97: Truy cập trang chủ | E97: 1. Truy cập trình duyệt 2. Truy cập đường dẫn : https://localhost:7011/ 3. Quan sát logo ở góc trái header | F97: Icon điện thoại màu xanh dương hiển thị bên trái; Text 'PhoneStore' màu đen, in đậm; Logo nằm góc trái header; Kích thước hợp lý | I97: High
A98: TC_GUI_HP_003 | B98: Header & Navbar | C98: Menu điều hướng hiển thị đúng 4 mục: Trang chủ, Sản phẩm, Về chúng tôi, Liên hệ | D98: Truy cập trang chủ | E98: 1. Truy cập trình duyệt 2. Truy cập đường dẫn : https://localhost:7011/ 3. Quan sát các mục menu trên header | F98: Hiển thị đủ 4 mục: 'Trang chủ', 'Sản phẩm', 'Về chúng tôi', 'Liên hệ'; Thứ tự đúng từ trái sang phải; Font chữ rõ ràng, màu tối; Căn giữa header | I98: High
A99: TC_GUI_HP_004 | B99: Header & Navbar | C99: Menu item hiển thị hiệu ứng hover khi rê chuột | D99: Truy cập trang chủ | E99: 1. Truy cập trình duyệt 2. Truy cập đường dẫn : https://localhost:7011/ 3. Rê chuột lần lượt qua 4 mục menu 4. Quan sát thay đổi | F99: Mỗi menu item thay đổi màu hoặc xuất hiện underline khi hover; Con trỏ chuyển pointer; Hiệu ứng transition mượt mà | I99: Medium
A100: TC_GUI_HP_005 | B100: Header & Navbar | C100: Ô tìm kiếm hiển thị đúng vị trí, icon kính lúp và placeholder | D100: Truy cập trang chủ | E100: 1. Truy cập trình duyệt 2. Truy cập đường dẫn : https://localhost:7011/ 3. Quan sát ô tìm kiếm trên header | F100: Ô tìm kiếm nằm bên phải menu; Icon kính lúp hiển thị bên trái ô; Placeholder 'Tìm kiếm...' màu xám nhạt; Viền ô rõ ràng; Bo góc tròn | I100: High
A101: TC_GUI_HP_006 | B101: Header & Navbar | C101: Ô tìm kiếm highlight viền khi được focus | D101: Truy cập trang chủ | E101: 1. Truy cập trình duyệt 2. Truy cập đường dẫn : https://localhost:7011/ 3. Click vào ô tìm kiếm 4. Quan sát viền | F101: Viền ô tìm kiếm chuyển màu xanh khi focus; Placeholder biến mất; Con nháy xuất hiện | I101: Medium
